Workbook
Name ACTION: #REF!
Name LOCAL_DATE_SEPARATOR: #REF!
Name LOCAL_DAY_FORMAT: #REF!
Name LOCAL_HOUR_FORMAT: #REF!
Name LOCAL_MINUTE_FORMAT: #REF!
Name LOCAL_MONTH_FORMAT: #REF!
Name LOCAL_SECOND_FORMAT: #REF!
Name LOCAL_TIME_SEPARATOR: #REF!
Name LOCAL_YEAR_FORMAT: #REF!
Name _Toc301930468: TestDesign!$B$219
Name _Toc301930478: TestDesign!$B$379

Sheet Cover
B2: TEST CASE
B4: Project Name | C4: Kiểm thử hệ thống Webmail Gmail | F4: Creator | G4: Trương Trọng Nhân - 23130217
B5: Project Code | C5: GMAIL | F5: Reviewer/Approver
B6: Document Code | C6: =C5&"_TestCase_V1.0" | F6: Issue Date | G6: 46312
F7: Version | G7: 1.0
B10: Record of change
B11: Effective Date | C11: Version | D11: Change Item | E11: *A,D,M | F11: Change description | G11: Reference
B12: 46312 | C12: 1.0 | D12: TestDesign, Search Mail, Reply, Reply All, Forward, Manage Labels | E12: A | F12: Thiết kế Test Design và Test Case chi tiết cho 3 chức năng của Thành viên 3: Tìm kiếm thư (Search Mail - 30 TC), Trả lời & Chuyển tiếp (Reply-Forward - 23 TC) và Quản lý Nhãn (Manage Labels - 27 TC). Tổng cộng: 80 Test Cases. | G12: Ứng dụng Web Gmail (mail.google.com)

Sheet Test case List
D1: TEST CASE LIST
B3: Project Name | D3: =Cover!C4
B4: Project Code | D4: =Cover!C5
B5: Test Environment Setup Description | D5: 1. Ứng dụng Web: https://mail.google.com 2. Trình duyệt: Google Chrome (Sử dụng Profile đã đăng nhập sẵn) 3. Công cụ Automation: Java + Selenium WebDriver + TestNG (POM) 4. Hệ điều hành: Windows 10/11
B8: No | C8: Function Name | D8: Sheet Name | E8: Description | F8: Pre-Condition
B9: 1 | C9: Tìm kiếm thư (Cơ bản & Nâng cao) | D9: Search Mail | E9: Kiểm thử thanh tìm kiếm từ khóa và bộ lọc tìm kiếm nâng cao (30 Test Cases). | F9: Đã đăng nhập sẵn vào hộp thư Gmail qua Chrome Profile.
B10: 2 | C10: Trả lời thư (Reply) | D10: Reply | E10: Kiểm thử chức năng Trả lời thư (9 Test Cases). | F10: Đã đăng nhập Gmail và có sẵn email trong Hộp thư đến.
B11: 3 | C11: Trả lời tất cả (Reply All) | D11: Reply All | E11: Kiểm thử chức năng Trả lời tất cả (6 Test Cases). | F11: Đã đăng nhập Gmail và có sẵn email trong Hộp thư đến.
B12: 4 | C12: Chuyển tiếp thư (Forward) | D12: Forward | E12: Kiểm thử chức năng Chuyển tiếp (8 Test Cases). | F12: Đã đăng nhập Gmail và có sẵn email trong Hộp thư đến.
B13: 5 | C13: Quản lý Nhãn (Thêm, Sửa, Xóa & Gán nhãn) | D13: Manage Labels | E13: Kiểm thử tạo mới, sửa tên, đổi màu, xóa nhãn và gán nhãn phân loại (27 Test Cases). | F13: Đã đăng nhập sẵn vào hộp thư Gmail qua Chrome Profile.

Sheet TestDesign
A1: Requirement Level 1 | B1: Requirement Level 2 | C1: Requirement Level 3 | D1: Test Criteria | E1: Test Type | F1: Note
A2: 3.1 Tìm kiếm thư | B2: 3.1.1 Tìm kiếm cơ bản | C2: Hiển thị giao diện | D2: Kiểm tra hiển thị thanh tìm kiếm và nút [Hiển thị tùy chọn tìm kiếm] tại Hộp thư đến | E2: GUI
D3: Kiểm tra hiển thị danh sách gợi ý tự động khi gõ từ khóa vào thanh tìm kiếm | E3: GUI
C4: Tìm theo từ khóa | D4: Kiểm tra tìm kiếm với từ khóa hợp lệ có trong Tiêu đề thư (Subject) | E4: Function
D5: Kiểm tra tìm kiếm với từ khóa hợp lệ có trong Nội dung thư (Body) | E5: Function
D6: Kiểm tra tìm kiếm với từ khóa không tồn tại trong hộp thư | E6: Function | F6: Hiện thông báo không có kết quả
D7: Kiểm tra tìm kiếm không phân biệt chữ HOA và chữ thường | E7: Function
D8: Kiểm tra tìm kiếm với từ khóa có khoảng trắng ở đầu và cuối | E8: Function | F8: Tự động cắt khoảng trắng thừa
D9: Kiểm tra tìm kiếm khi chỉ nhập toàn khoảng trắng (Space) | E9: Function
D10: Kiểm tra tìm kiếm với chuỗi ký tự đặc biệt (!@#$%^&*) | E10: Function
D11: Kiểm tra xóa nhanh từ khóa bằng nút [X] trên thanh tìm kiếm | E11: Function
B12: 3.1.2 Tìm kiếm nâng cao | C12: Hiển thị giao diện | D12: Kiểm tra mở biểu mẫu Tìm kiếm nâng cao khi nhấn nút [Hiển thị tùy chọn tìm kiếm] | E12: GUI
D13: Kiểm tra giá trị mặc định của các trường trong biểu mẫu Tìm kiếm nâng cao | E13: GUI | F13: Phạm vi = Tất cả thư, Ngày = 1 ngày
C14: Lọc đơn điều kiện | D14: Kiểm tra lọc theo trường [Từ] (From) với địa chỉ email người gửi hợp lệ | E14: Function
D15: Kiểm tra lọc theo trường [Từ] (From) với email không có thư nào trong hệ thống | E15: Function
D16: Kiểm tra lọc theo trường [Đến] (To) với địa chỉ email người nhận hợp lệ | E16: Function
D17: Kiểm tra lọc theo trường [Tiêu đề] (Subject) với từ khóa hợp lệ | E17: Function
D18: Kiểm tra lọc theo trường [Có các từ] (Has the words) | E18: Function
D19: Kiểm tra lọc theo trường [Không có] (Doesn't have) để loại trừ từ khóa | E19: Function
D20: Kiểm tra lọc theo [Kích thước] (Size) - Lớn hơn X MB | E20: Function
D21: Kiểm tra lọc theo [Kích thước] (Size) - Nhỏ hơn X MB | E21: Function
D22: Kiểm tra lọc theo [Ngày trong khoảng] (Date within: 1 tuần) | E22: Function
D23: Kiểm tra lọc khi tích chọn ô [Có tệp đính kèm] (Has attachment) | E23: Function
D24: Kiểm tra lọc theo phạm vi [Tìm kiếm] (Hộp thư đến, Thư đã gửi, v.v.) | E24: Function
C25: Lọc kết hợp | D25: Kiểm tra tìm kiếm kết hợp trường [Từ] VÀ [Có tệp đính kèm] | E25: Function
D26: Kiểm tra tìm kiếm kết hợp trường [Tiêu đề] VÀ [Ngày trong khoảng] | E26: Function
D27: Kiểm tra tìm kiếm với các điều kiện mâu thuẫn nhau (Không có thư khớp) | E27: Function
D28: Kiểm tra cú pháp toán tử tự động sinh ra trên thanh tìm kiếm sau khi bấm [Tìm kiếm] | E28: Function | F28: VD: from:(abc) has:attachment
D29: Kiểm tra nhấn nút [Tìm kiếm] khi để trống toàn bộ các trường trong biểu mẫu | E29: Function
D30: Kiểm tra lọc theo [Kích thước] khi nhập chữ hoặc ký tự không hợp lệ | E30: Function
D31: Kiểm tra lọc kết hợp trường [Có các từ] VÀ [Không có] | E31: Function
A32: 3.2 Trả lời & Chuyển tiếp | B32: 3.2.1 Trả lời thư (Reply) | C32: Hiển thị giao diện | D32: Kiểm tra mở khung soạn thảo khi nhấn nút [Trả lời] (Reply) trong chi tiết thư | E32: GUI | F32: Tự động điền người gửi gốc vào ô [Đến]
C33: Gửi thư trả lời | D33: Kiểm tra gửi thư trả lời thành công với nội dung văn bản hợp lệ | E33: Function
D34: Kiểm tra gửi thư trả lời có thêm người nhận CC và BCC | E34: Function
D35: Kiểm tra gửi thư trả lời có đính kèm tệp tin từ máy tính | E35: Function
D36: Kiểm tra chỉnh sửa Tiêu đề thư (Edit subject) khi trả lời | E36: Function | F36: Tạo thành luồng hội thoại mới
D37: Kiểm tra nhấn [Gửi] trả lời khi xóa trống người nhận ở ô [Đến] | E37: Function | F37: Hiển thị hộp thoại báo lỗi
D38: Kiểm tra hủy thư nháp đang trả lời bằng nút [Hủy thư nháp] (Biểu tượng thùng rác) | E38: Function
D39: Kiểm tra gửi thư trả lời với nội dung rất dài (khoảng 5000 ký tự) | E39: Function
D40: Kiểm tra gửi thư trả lời có chèn liên kết (Insert link) | E40: Function
...

Sheet Search Mail
A2: Module Code | B2: SearchMail | J2: Passed
A3: Test requirement | B3: Tìm kiếm thư (Cơ bản & Nâng cao) | J3: Failed
A4: Tester | B4: Trương Trọng Nhân | J4: Blocked
A5: Passed | B5: Failed | C5: Untested | D5: Blocked | E5: Skipped | F5: Number of Test cases | J5: Untested
A6: =COUNTIF(F9:F996,"Passed") | B6: =COUNTIF(F9:F996,"Failed") | C6: =F6-E6-D6-B6-A6 | D6: =COUNTIF(F$9:F$996,"Blocked") | E6: =COUNTIF(F$9:F$996,"Skipped") | F6: =COUNTA(A9:A996) | J6: Skipped
A8: ID | B8: Test Case Description | C8: Test Case Procedure | D8: Expected Output | E8: Inter-test case Dependence | F8: Result | G8: Test date | H8: Note
A9: =IF(OR(B9<>"",D9<>""),"["&TEXT($B$2,"##")&"-"&TEXT(ROW()-8,"##")&"]","") | B9: Kiểm tra hiển thị thanh tìm kiếm và nút tùy chọn | C9: Điều kiện tiên quyết: + Đã đăng nhập vào màn hình Hộp thư đến Gmail Các bước thực hiện: 1. Quan sát khu vực thanh công cụ phía trên cùng của Hộp thư đến | D9: 1. Hiển thị rõ thanh tìm kiếm có chữ gợi ý "Tìm kiếm trong thư" và biểu tượng [Hiển thị tùy chọn tìm kiếm] ở bên phải. | F9: Untested
A10: =IF(OR(B10<>"",D10<>""),"["&TEXT($B$2,"##")&"-"&TEXT(ROW()-8,"##")&"]","") | B10: Kiểm tra danh sách gợi ý khi gõ từ khóa | C10: Điều kiện tiên quyết: + Trong hộp thư có sẵn các email chứa từ "Báo cáo" Các bước thực hiện: 1. Nhấp chuột vào thanh tìm kiếm 2. Nhập từ khóa ["Báo cáo"] và chờ 1 giây | D10: 2. Hiển thị danh sách xổ xuống (Auto-suggest) bên dưới thanh tìm kiếm gợi ý các từ khóa và email liên quan đến "Báo cáo". | F10: Untested
A11: =IF(OR(B11<>"",D11<>""),"["&TEXT($B$2,"##")&"-"&TEXT(ROW()-8,"##")&"]","") | B11: Tìm kiếm với từ khóa hợp lệ trong Tiêu đề | C11: Điều kiện tiên quyết: + Có ít nhất 1 email có Tiêu đề chứa ["Kế hoạch dự án"] Các bước thực hiện: 1. Nhập ["Kế hoạch dự án"] vào thanh tìm kiếm 2. Nhấn phím [Enter] | D11: 2. Hiển thị danh sách kết quả gồm các email có chứa cụm từ "Kế hoạch dự án" trong phần Tiêu đề. | F11: Untested
A12: =IF(OR(B12<>"",D12<>""),"["&TEXT($B$2,"##")&"-"&TEXT(ROW()-8,"##")&"]","") | B12: Tìm kiếm với từ khóa hợp lệ trong Nội dung | C12: Điều kiện tiên quyết: + Có ít nhất 1 email có Nội dung chứa ["MeetingLink2026"] Các bước thực hiện: 1. Nhập ["MeetingLink2026"] vào thanh tìm kiếm 2. Nhấn phím [Enter] | D12: 2. Hiển thị danh sách kết quả gồm các email có chứa từ "MeetingLink2026" trong phần Nội dung thư. | F12: Untested
A13: =IF(OR(B13<>"",D13<>""),"["&TEXT($B$2,"##")&"-"&TEXT(ROW()-8,"##")&"]","") | B13: Tìm kiếm với từ khóa không tồn tại | C13: Các bước thực hiện: 1. Nhập từ khóa không có thật ["xyz_khong_ton_tai_99999"] vào thanh tìm kiếm 2. Nhấn phím [Enter] | D13: 2. Hiển thị thông báo "Không có thư nào khớp với tìm kiếm của bạn." (No messages matched your search). | F13: Untested
A14: =IF(OR(B14<>"",D14<>""),"["&TEXT($B$2,"##")&"-"&TEXT(ROW()-8,"##")&"]","") | B14: Tìm kiếm không phân biệt chữ HOA - thường | C14: Điều kiện tiên quyết: + Có email chứa từ ["khẩn cấp"] Các bước thực hiện: 1. Nhập ["KHẨN CẤP"] (chữ in hoa) vào thanh tìm kiếm rồi nhấn [Enter] 2. Nhập ["khẩn cấp"] (chữ thường) vào thanh tìm kiếm rồi nhấn [Enter] | D14: 1. Hiển thị danh sách các email chứa từ "khẩn cấp". 2. Danh sách kết quả trả về ở bước 2 giống hệt với bước 1. | F14: Untested
A15: =IF(OR(B15<>"",D15<>""),"["&TEXT($B$2,"##")&"-"&TEXT(ROW()-8,"##")&"]","") | B15: Tìm kiếm từ khóa có khoảng trắng ở đầu và cuối | C15: Điều kiện tiên quyết: + Có email chứa từ ["Hóa đơn"] Các bước thực hiện: 1. Nhập [" Hóa đơn "] vào thanh tìm kiếm 2. Nhấn phím [Enter] | D15: 2. Hệ thống tự động loại bỏ khoảng trắng thừa ở 2 đầu và hiển thị các email chứa từ "Hóa đơn". | F15: Untested
A16: =IF(OR(B16<>"",D16<>""),"["&TEXT($B$2,"##")&"-"&TEXT(ROW()-8,"##")&"]","") | B16: Tìm kiếm khi chỉ nhập khoảng trắng (Space) | C16: Các bước thực hiện: 1. Nhập 5 ký tự khoảng trắng [" "] vào thanh tìm kiếm 2. Nhấn phím [Enter] | D16: 2. Hệ thống không bị lỗi, giữ nguyên danh sách thư hiện tại hoặc báo không có kết quả khớp. | F16: Untested
A17: =IF(OR(B17<>"",D17<>""),"["&TEXT($B$2,"##")&"-"&TEXT(ROW()-8,"##")&"]","") | B17: Tìm kiếm với chuỗi ký tự đặc biệt | C17: Các bước thực hiện: 1. Nhập chuỗi ký tự đặc biệt ["!@#$%^&*()"] vào thanh tìm kiếm 2. Nhấn phím [Enter] | D17: 2. Hệ thống xử lý bình thường, hiển thị thông báo "Không có thư nào khớp với tìm kiếm của bạn." | F17: Untested
A18: =IF(OR(B18<>"",D18<>""),"["&TEXT($B$2,"##")&"-"&TEXT(ROW()-8,"##")&"]","") | B18: Xóa nhanh từ khóa tìm kiếm bằng nút [X] | C18: Các bước thực hiện: 1. Nhập từ khóa ["Báo cáo"] vào thanh tìm kiếm 2. Nhấp vào nút biểu tượng dấu [X] (Xóa tìm kiếm) ở góc phải thanh tìm kiếm | D18: 1. Từ khóa "Báo cáo" và nút [X] hiển thị trên thanh tìm kiếm. 2. Ô tìm kiếm được xóa trắng về trạng thái ban đầu. | F18: Untested
A19: =IF(OR(B19<>"",D19<>""),"["&TEXT($B$2,"##")&"-"&TEXT(ROW()-8,"##")&"]","") | B19: Mở biểu mẫu Tìm kiếm nâng cao | C19: Các bước thực hiện: 1. Tại thanh tìm kiếm, nhấp vào biểu tượng [Hiển thị tùy chọn tìm kiếm] (hình thanh trượt bên phải) | D19: 1. Biểu mẫu Tìm kiếm nâng cao xổ xuống hiển thị đầy đủ các trường: Từ, Đến, Tiêu đề, Có các từ, Không có, Kích thước, Ngày trong khoảng, Phạm vi Tìm kiếm, Có tệp đính kèm và nút [Tìm kiếm]. | F19: Untested
A20: =IF(OR(B20<>"",D20<>""),"["&TEXT($B$2,"##")&"-"&TEXT(ROW()-8,"##")&"]","") | B20: Kiểm tra giá trị mặc định trong Tìm kiếm nâng cao | C20: Các bước thực hiện: 1. Nhấp mở biểu tượng [Hiển thị tùy chọn tìm kiếm] 2. Quan sát giá trị mặc định của tất cả các trường | D20: 2. Các ô nhập văn bản đều trống; [Kích thước] = "lớn hơn", "MB"; [Ngày trong khoảng] = "1 ngày"; [Tìm kiếm] = "Tất cả thư"; ô [Có tệp đính kèm] chưa được tích. | F20: Untested
... A38: =IF(OR(B38<>"",D38<>""),"["&TEXT($B$2,"##")&"-"&TEXT(ROW()-8,"##")&"]","") | B38: Lọc kết hợp: [Có các từ] + [Không có] | C38: Điều kiện tiên quyết: + Có email chứa cả từ ["Báo cáo"] và ["Nháp"], và có email chỉ chứa từ ["Báo cáo"] Các bước thực hiện: 1. Mở biểu mẫu Tìm kiếm nâng cao 2. Nhập ["Báo cáo"] vào ô [Có các từ] và nhập ["Nháp"] vào ô [Không có] 3. Nhấp nút [Tìm kiếm] | D38: 3. Chỉ hiển thị các email có chứa từ "Báo cáo" VÀ KHÔNG chứa từ "Nháp". | F38: Untested

Sheet Reply
A2: Module Code | B2: Reply | J2: Passed
A3: Test requirement | B3: Trả lời thư (Reply) | J3: Failed
A4: Tester | B4: Trương Trọng Nhân | J4: Blocked
A5: Passed | B5: Failed | C5: Untested | D5: Blocked | E5: Skipped | F5: Number of Test cases | J5: Untested
A6: =COUNTIF(F9:F996,"Passed") | B6: =COUNTIF(F9:F996,"Failed") | C6: =F6-E6-D6-B6-A6 | D6: =COUNTIF(F$9:F$996,"Blocked") | E6: =COUNTIF(F$9:F$996,"Skipped") | F6: =COUNTA(A9:A996) | J6: Skipped
A8: ID | B8: Test Case Description | C8: Test Case Procedure | D8: Expected Output | E8: Inter-test case Dependence | F8: Result | G8: Test date | H8: Note
A9: =IF(OR(B9<>"",D9<>""),"["&TEXT($B$2,"##")&"-"&TEXT(ROW()-8,"##")&"]","") | B9: Kiểm tra hiển thị khung Trả lời (Reply) | C9: Điều kiện tiên quyết: + Mở xem chi tiết 1 email trong Hộp thư đến Các bước thực hiện: 1. Nhấp nút [Trả lời] (Reply) ở cuối nội dung thư | D9: 1. Khung soạn thảo trả lời mở ra ngay bên dưới thư; trường [Đến] (To) tự động điền sẵn địa chỉ của người gửi gốc. | F9: Untested
A10: =IF(OR(B10<>"",D10<>""),"["&TEXT($B$2,"##")&"-"&TEXT(ROW()-8,"##")&"]","") | B10: Gửi thư trả lời với nội dung hợp lệ | C10: Các bước thực hiện: 1. Trong khung Trả lời, nhập ["Cảm ơn, mình đã nhận được thông tin!"] vào nội dung 2. Nhấp nút [Gửi] (Send) | D10: 2. Hiển thị thông báo "Đã gửi thư" ở góc trái dưới; thư trả lời xuất hiện nối tiếp vào luồng hội thoại hiện tại. | E10: Reply-1 | F10: Untested
A11: =IF(OR(B11<>"",D11<>""),"["&TEXT($B$2,"##")&"-"&TEXT(ROW()-8,"##")&"]","") | B11: Gửi thư trả lời có thêm người nhận CC/BCC | C11: Các bước thực hiện: 1. Nhấp nút [Trả lời] 2. Nhấp mở [Cc] và [Bcc], nhập địa chỉ email hợp lệ 3. Nhập nội dung và nhấp nút [Gửi] | D11: 3. Thư trả lời được gửi thành công đến người gửi gốc cùng các địa chỉ trong CC và BCC. | F11: Untested
A12: =IF(OR(B12<>"",D12<>""),"["&TEXT($B$2,"##")&"-"&TEXT(ROW()-8,"##")&"]","") | B12: Gửi thư trả lời có đính kèm tệp từ máy tính | C12: Các bước thực hiện: 1. Nhấp nút [Trả lời] 2. Tải tệp ["tailieu.pdf"] lên thông qua chức năng Đính kèm tệp 3. Nhấp nút [Gửi] | D12: 2. Tệp "tailieu.pdf" hiển thị hoàn tất trong khung trả lời. 3. Thư trả lời được gửi đi kèm theo tệp đính kèm. | F12: Untested
A13: =IF(OR(B13<>"",D13<>""),"["&TEXT($B$2,"##")&"-"&TEXT(ROW()-8,"##")&"]","") | B13: Chỉnh sửa Tiêu đề thư khi trả lời | C13: Các bước thực hiện: 1. Nhấp nút [Trả lời] 2. Nhấp biểu tượng [Loại phản hồi] (góc trái trên khung trả lời) -> Chọn [Chỉnh sửa chủ đề] (Edit subject) 3. Nhập tiêu đề mới ["Chủ đề thảo luận mới"] rồi nhấn [Gửi] | D13: 2. Khung soạn thảo mở rộng cho phép sửa dòng Tiêu đề. 3. Thư được gửi đi và tách thành một luồng hội thoại (thread) mới độc lập. | F13: Untested
A14: =IF(OR(B14<>"",D14<>""),"["&TEXT($B$2,"##")&"-"&TEXT(ROW()-8,"##")&"]","") | B14: Nhấn [Gửi] trả lời khi xóa trống người nhận [Đến] | C14: Các bước thực hiện: 1. Nhấp nút [Trả lời] 2. Nhấp dấu [x] xóa bỏ người nhận trong ô [Đến] 3. Nhấp nút [Gửi] | D14: 3. Hiển thị hộp thoại báo lỗi "Vui lòng chỉ định ít nhất một người nhận." (Please specify at least one recipient). | F14: Untested
A15: =IF(OR(B15<>"",D15<>""),"["&TEXT($B$2,"##")&"-"&TEXT(ROW()-8,"##")&"]","") | B15: Hủy bỏ thư nháp đang trả lời | C15: Các bước thực hiện: 1. Nhấp nút [Trả lời] và gõ ["Nội dung nháp"] 2. Nhấp biểu tượng [Hủy thư nháp] (hình thùng rác ở góc dưới bên phải khung trả lời) | D15: 2. Khung soạn thảo trả lời đóng lại và bản nháp bị xóa bỏ. | F15: Untested
A16: =IF(OR(B16<>"",D16<>""),"["&TEXT($B$2,"##")&"-"&TEXT(ROW()-8,"##")&"]","") | B16: Gửi thư trả lời với nội dung rất dài | C16: Các bước thực hiện: 1. Nhấp nút [Trả lời] 2. Dán đoạn văn bản dài khoảng [5000 ký tự] vào khung nội dung 3. Nhấp nút [Gửi] | D16: 3. Hiển thị thông báo "Đã gửi thư"; thư trả lời được gửi thành công và nội dung hiển thị đầy đủ, không bị cắt cụt. | F16: Untested
A17: =IF(OR(B17<>"",D17<>""),"["&TEXT($B$2,"##")&"-"&TEXT(ROW()-8,"##")&"]","") | B17: Gửi thư trả lời có chèn liên kết (Insert link) | C17: Các bước thực hiện: 1. Nhấp nút [Trả lời] 2. Nhập [Xem tại đây], bôi đen cụm từ rồi nhấp biểu tượng [Chèn đường liên kết] (Insert link) 3. Nhập địa chỉ ["https://www.google.com"] và nhấp [OK] 4. Nhấp nút [Gửi] | D17: 3. Cụm từ được định dạng thành liên kết. 4. Thư được gửi thành công; trong thư đã gửi, cụm từ "Xem tại đây" nhấp được và dẫn đến "https://www.google.com". | F17: Untested

Sheet Reply All
A2: Module Code | B2: ReplyAll | J2: Passed
A3: Test requirement | B3: Trả lời tất cả (Reply All) | J3: Failed
A4: Tester | B4: Trương Trọng Nhân | J4: Blocked
A5: Passed | B5: Failed | C5: Untested | D5: Blocked | E5: Skipped | F5: Number of Test cases | J5: Untested
A6: =COUNTIF(F9:F996,"Passed") | B6: =COUNTIF(F9:F996,"Failed") | C6: =F6-E6-D6-B6-A6 | D6: =COUNTIF(F$9:F$996,"Blocked") | E6: =COUNTIF(F$9:F$996,"Skipped") | F6: =COUNTA(A9:A996) | J6: Skipped
A8: ID | B8: Test Case Description | C8: Test Case Procedure | D8: Expected Output | E8: Inter-test case Dependence | F8: Result | G8: Test date | H8: Note
A9: =IF(OR(B9<>"",D9<>""),"["&TEXT($B$2,"##")&"-"&TEXT(ROW()-8,"##")&"]","") | B9: Kiểm tra hiển thị khung Trả lời tất cả (Reply All) | C9: Điều kiện tiên quyết: + Mở một email có nhiều người nhận trong mục Đến và CC Các bước thực hiện: 1. Nhấp nút [Trả lời tất cả] (Reply all) | D9: 1. Khung soạn thảo mở ra, giữ nguyên người gửi gốc ở mục [Đến] và toàn bộ những người nhận khác ở mục [Cc]. | F9: Untested
A10: =IF(OR(B10<>"",D10<>""),"["&TEXT($B$2,"##")&"-"&TEXT(ROW()-8,"##")&"]","") | B10: Gửi phản hồi bằng chức năng Trả lời tất cả | C10: Các bước thực hiện: 1. Nhấp nút [Trả lời tất cả] 2. Nhập nội dung ["Đã rõ, cảm ơn mọi người"] 3. Nhấp nút [Gửi] | D10: 3. Thư phản hồi được gửi thành công tới tất cả các thành viên trong cuộc trò chuyện. | F10: Untested
A11: =IF(OR(B11<>"",D11<>""),"["&TEXT($B$2,"##")&"-"&TEXT(ROW()-8,"##")&"]","") | B11: Trả lời tất cả có thêm người nhận Bcc | C11: Điều kiện tiên quyết: + Mở một email có nhiều người nhận trong mục Đến và CC Các bước thực hiện: 1. Nhấp nút [Trả lời tất cả] 2. Nhấp mở [Bcc] và nhập ["23130217@st.hcmuaf.edu.vn"] 3. Nhập nội dung và nhấp nút [Gửi] | D11: 3. Thư được gửi thành công đến toàn bộ người nhận gốc và địa chỉ Bcc mới; những người nhận khác không nhìn thấy địa chỉ Bcc. | F11: Untested
A12: =IF(OR(B12<>"",D12<>""),"["&TEXT($B$2,"##")&"-"&TEXT(ROW()-8,"##")&"]","") | B12: Trả lời tất cả có đính kèm tệp từ máy tính | C12: Các bước thực hiện: 1. Nhấp nút [Trả lời tất cả] 2. Tải tệp ["tailieu.pdf"] lên thông qua chức năng Đính kèm tệp 3. Nhấp nút [Gửi] | D12: 2. Tệp "tailieu.pdf" hiển thị hoàn tất trong khung trả lời. 3. Thư được gửi đi kèm tệp đính kèm đến toàn bộ người nhận. | F12: Untested
A13: =IF(OR(B13<>"",D13<>""),"["&TEXT($B$2,"##")&"-"&TEXT(ROW()-8,"##")&"]","") | B13: Gỡ một người nhận khỏi mục [Cc] trước khi gửi Trả lời tất cả | C13: Điều kiện tiên quyết: + Mở một email có nhiều người nhận, trong đó có ["23130217@st.hcmuaf.edu.vn"] ở mục CC Các bước thực hiện: 1. Nhấp nút [Trả lời tất cả] 2. Nhấp dấu [x] cạnh ["23130217@st.hcmuaf.edu.vn"] trong ô [Cc] 3. Nhập nội dung và nhấp nút [Gửi] | D13: 2. Địa chỉ "23130217@st.hcmuaf.edu.vn" bị gỡ khỏi ô [Cc]. 3. Thư được gửi thành công đến những người nhận còn lại; "23130217@st.hcmuaf.edu.vn" không nhận được thư. | F13: Untested
A14: =IF(OR(B14<>"",D14<>""),"["&TEXT($B$2,"##")&"-"&TEXT(ROW()-8,"##")&"]","") | B14: Gửi Trả lời tất cả khi để trống nội dung | C14: Các bước thực hiện: 1. Nhấp nút [Trả lời tất cả] 2. Để trống phần nội dung thư 3. Nhấp nút [Gửi] | D14: 3. Hiển thị hộp thoại cảnh báo gửi thư không có nội dung; thư chỉ được gửi đi khi người dùng xác nhận gửi. | F14: Untested

Sheet Forward
A2: Module Code | B2: Forward | J2: Passed
A3: Test requirement | B3: Chuyển tiếp thư (Forward) | J3: Failed
A4: Tester | B4: Trương Trọng Nhân | J4: Blocked
A5: Passed | B5: Failed | C5: Untested | D5: Blocked | E5: Skipped | F5: Number of Test cases | J5: Untested
A6: =COUNTIF(F9:F996,"Passed") | B6: =COUNTIF(F9:F996,"Failed") | C6: =F6-E6-D6-B6-A6 | D6: =COUNTIF(F$9:F$996,"Blocked") | E6: =COUNTIF(F$9:F$996,"Skipped") | F6: =COUNTA(A9:A996) | J6: Skipped
A8: ID | B8: Test Case Description | C8: Test Case Procedure | D8: Expected Output | E8: Inter-test case Dependence | F8: Result | G8: Test date | H8: Note
A9: =IF(OR(B9<>"",D9<>""),"["&TEXT($B$2,"##")&"-"&TEXT(ROW()-8,"##")&"]","") | B9: Kiểm tra hiển thị khung Chuyển tiếp (Forward) | C9: Điều kiện tiên quyết: + Mở một email có sẵn nội dung văn bản và tệp đính kèm Các bước thực hiện: 1. Nhấp nút [Chuyển tiếp] (Forward) | D9: 1. Khung chuyển tiếp mở ra với ô [Đến] để trống, bên dưới giữ nguyên thông tin "---------- Forwarded message ---------" và các tệp đính kèm gốc. | F9: Untested
A10: =IF(OR(B10<>"",D10<>""),"["&TEXT($B$2,"##")&"-"&TEXT(ROW()-8,"##")&"]","") | B10: Chuyển tiếp thư đến 1 người nhận hợp lệ | C10: Các bước thực hiện: 1. Nhấp nút [Chuyển tiếp] 2. Nhập ["nahnnhan04@gmail.com"] vào ô [Đến] 3. Nhấp nút [Gửi] | D10: 3. Thư được chuyển tiếp thành công, hiển thị thông báo "Đã gửi thư". | F10: Untested
A11: =IF(OR(B11<>"",D11<>""),"["&TEXT($B$2,"##")&"-"&TEXT(ROW()-8,"##")&"]","") | B11: Chuyển tiếp thư đến nhiều người nhận cùng lúc | C11: Các bước thực hiện: 1. Nhấp nút [Chuyển tiếp] 2. Nhập ["nahnnhan04@gmail.com", "23130217@st.hcmuaf.edu.vn"] vào ô [Đến] 3. Nhấp nút [Gửi] | D11: 3. Thư được chuyển tiếp thành công đến cả 2 địa chỉ người nhận. | F11: Untested
A12: =IF(OR(B12<>"",D12<>""),"["&TEXT($B$2,"##")&"-"&TEXT(ROW()-8,"##")&"]","") | B12: Chuyển tiếp thư với địa chỉ email sai định dạng | C12: Các bước thực hiện: 1. Nhấp nút [Chuyển tiếp] 2. Nhập ["email_sai@@com"] vào ô [Đến] 3. Nhấp nút [Gửi] | D12: 3. Hiển thị hộp thoại báo lỗi địa chỉ trong trường "Đến" không được nhận dạng. | F12: Untested
A13: =IF(OR(B13<>"",D13<>""),"["&TEXT($B$2,"##")&"-"&TEXT(ROW()-8,"##")&"]","") | B13: Nhấn [Gửi] chuyển tiếp khi bỏ trống ô [Đến] | C13: Các bước thực hiện: 1. Nhấp nút [Chuyển tiếp] 2. Để trống ô [Đến] và nhấp nút [Gửi] | D13: 2. Hiển thị hộp thoại báo lỗi "Vui lòng chỉ định ít nhất một người nhận." | F13: Untested
A14: =IF(OR(B14<>"",D14<>""),"["&TEXT($B$2,"##")&"-"&TEXT(ROW()-8,"##")&"]","") | B14: Xóa tệp đính kèm gốc trước khi Chuyển tiếp | C14: Điều kiện tiên quyết: + Mở một email có sẵn tệp đính kèm Các bước thực hiện: 1. Nhấp nút [Chuyển tiếp] 2. Nhấp dấu [x] để gỡ bỏ tệp đính kèm trong khung chuyển tiếp 3. Nhập người nhận vào ô [Đến] và nhấp [Gửi] | D14: 2. Tệp đính kèm bị xóa khỏi bản nháp chuyển tiếp. 3. Thư chuyển tiếp được gửi đi chỉ gồm văn bản, không còn tệp đính kèm gốc. | F14: Untested
A15: =IF(OR(B15<>"",D15<>""),"["&TEXT($B$2,"##")&"-"&TEXT(ROW()-8,"##")&"]","") | B15: Chuyển tiếp thư có thêm người nhận CC/BCC | C15: Các bước thực hiện: 1. Nhấp nút [Chuyển tiếp] 2. Nhập ["nahnnhan04@gmail.com"] vào ô [Đến] 3. Nhấp mở [Cc] và [Bcc], nhập địa chỉ email hợp lệ 4. Nhấp nút [Gửi] | D15: 4. Thư được chuyển tiếp thành công đến người nhận chính cùng các địa chỉ trong CC và BCC. | F15: Untested
A16: =IF(OR(B16<>"",D16<>""),"["&TEXT($B$2,"##")&"-"&TEXT(ROW()-8,"##")&"]","") | B16: Chỉnh sửa nội dung trước khi chuyển tiếp thư | C16: Các bước thực hiện: 1. Nhấp nút [Chuyển tiếp] 2. Nhập ["nahnnhan04@gmail.com"] vào ô [Đến] 3. Nhập thêm lời nhắn ["Nhờ bạn xem giúp"] phía trên phần nội dung gốc 4. Nhấp nút [Gửi] | D16: 4. Thư được chuyển tiếp thành công, gồm lời nhắn mới và nội dung gốc được giữ nguyên bên dưới. | F16: Untested

Sheet Manage Labels
A2: Module Code | B2: ManageLabels | J2: Passed
A3: Test requirement | B3: Quản lý Nhãn (Thêm, Sửa, Xóa & Gán nhãn) | J3: Failed
A4: Tester | B4: Trương Trọng Nhân | J4: Blocked
A5: Passed | B5: Failed | C5: Untested | D5: Blocked | E5: Skipped | F5: Number of Test cases | J5: Untested
A6: =COUNTIF(F9:F996,"Passed") | B6: =COUNTIF(F9:F996,"Failed") | C6: =F6-E6-D6-B6-A6 | D6: =COUNTIF(F$9:F$996,"Blocked") | E6: =COUNTIF(F$9:F$996,"Skipped") | F6: =COUNTA(A9:A996) | J6: Skipped
A8: ID | B8: Test Case Description | C8: Test Case Procedure | D8: Expected Output | E8: Inter-test case Dependence | F8: Result | G8: Test date | H8: Note
A9: =IF(OR(B9<>"",D9<>""),"["&TEXT($B$2,"##")&"-"&TEXT(ROW()-8,"##")&"]","") | B9: Kiểm tra hiển thị hộp thoại tạo [Nhãn mới] | C9: Các bước thực hiện: 1. Tại thanh menu bên trái, nhấp vào dấu [+] bên cạnh mục "Nhãn" (Labels) | D9: 1. Hộp thoại [Nhãn mới] (New label) hiển thị gồm ô nhập tên nhãn, tùy chọn [Đặt nhãn bên trong] và nút [Tạo] / [Hủy]. | F9: Untested
A10: =IF(OR(B10<>"",D10<>""),"["&TEXT($B$2,"##")&"-"&TEXT(ROW()-8,"##")&"]","") | B10: Tạo nhãn mới với tên hợp lệ | C10: Các bước thực hiện: 1. Nhấp dấu [+] tạo nhãn mới ở menu trái 2. Nhập tên nhãn ["DuAn_2026"] 3. Nhấp nút [Tạo] (Create) | D10: 3. Hộp thoại đóng lại; thông báo 'Đã tạo nhãn "DuAn_2026"' xuất hiện và nhãn "DuAn_2026" hiển thị ở danh sách bên trái. | F10: Untested
A11: =IF(OR(B11<>"",D11<>""),"["&TEXT($B$2,"##")&"-"&TEXT(ROW()-8,"##")&"]","") | B11: Tạo nhãn con lồng bên dưới nhãn cha | C11: Điều kiện tiên quyết: + Đã có sẵn nhãn cha ["DuAn_2026"] Các bước thực hiện: 1. Nhấp dấu [+] tạo nhãn mới 2. Nhập tên ["GiaiDoan_1"] 3. Tích chọn [Đặt nhãn bên trong] và chọn ["DuAn_2026"] 4. Nhấp nút [Tạo] | D11: 4. Nhãn con "GiaiDoan_1" được tạo thành công và nằm thụt lề bên dưới nhãn cha "DuAn_2026". | F11: Untested
A12: =IF(OR(B12<>"",D12<>""),"["&TEXT($B$2,"##")&"-"&TEXT(ROW()-8,"##")&"]","") | B12: Tạo nhãn mới khi để trống tên nhãn | C12: Các bước thực hiện: 1. Nhấp dấu [+] tạo nhãn mới 2. Để trống ô nhập tên nhãn 3. Quan sát hoặc nhấp vào nút [Tạo] | D12: 3. Hệ thống không cho phép tạo nhãn rỗng (Nút [Tạo] bị vô hiệu hóa hoặc hiện thông báo nhắc nhập tên). | F12: Untested
A13: =IF(OR(B13<>"",D13<>""),"["&TEXT($B$2,"##")&"-"&TEXT(ROW()-8,"##")&"]","") | B13: Tạo nhãn mới trùng tên với nhãn đã có | C13: Điều kiện tiên quyết: + Nhãn ["DuAn_2026"] đã tồn tại Các bước thực hiện: 1. Nhấp dấu [+] tạo nhãn mới 2. Nhập lại tên ["DuAn_2026"] 3. Nhấp nút [Tạo] | D13: 3. Hiển thị thông báo lỗi "Tên nhãn bạn chọn đã tồn tại. Vui lòng thử tên khác." | F13: Untested
A14: =IF(OR(B14<>"",D14<>""),"["&TEXT($B$2,"##")&"-"&TEXT(ROW()-8,"##")&"]","") | B14: Hủy thao tác tạo nhãn mới | C14: Các bước thực hiện: 1. Nhấp dấu [+] tạo nhãn mới 2. Nhập ["Nhan_Tam"] 3. Nhấp nút [Hủy] (Cancel) | D14: 3. Hộp thoại đóng lại và nhãn "Nhan_Tam" KHÔNG xuất hiện trên thanh menu trái. | F14: Untested
A15: =IF(OR(B15<>"",D15<>""),"["&TEXT($B$2,"##")&"-"&TEXT(ROW()-8,"##")&"]","") | B15: Đổi tên một nhãn đang tồn tại | C15: Điều kiện tiên quyết: + Nhãn ["DuAn_2026"] đang tồn tại Các bước thực hiện: 1. Di chuột vào nhãn ["DuAn_2026"] ở menu trái -> Nhấp biểu tượng 3 chấm dọc 2. Chọn [Chỉnh sửa] (Edit) 3. Sửa tên thành ["DuAn_CapNhat"] rồi nhấp [Lưu] | D15: 3. Tên nhãn trên thanh menu trái và trên các email đã gán nhãn được cập nhật thành "DuAn_CapNhat". | F15: Untested
A16: =IF(OR(B16<>"",D16<>""),"["&TEXT($B$2,"##")&"-"&TEXT(ROW()-8,"##")&"]","") | B16: Đổi màu sắc nhận diện cho nhãn | C16: Các bước thực hiện: 1. Nhấp biểu tượng 3 chấm dọc cạnh nhãn ["DuAn_CapNhat"] 2. Di chuột vào mục [Màu nhãn] (Label color) -> Chọn màu Xanh lá | D16: 2. Biểu tượng của nhãn ở menu trái và thẻ nhãn đính trên email đổi sang màu Xanh lá ngay lập tức. | E16: ManageLabels-7 | F16: Untested
A17: =IF(OR(B17<>"",D17<>""),"["&TEXT($B$2,"##")&"-"&TEXT(ROW()-8,"##")&"]","") | B17: Ẩn nhãn khỏi danh sách menu bên trái | C17: Các bước thực hiện: 1. Nhấp biểu tượng 3 chấm dọc cạnh nhãn ["DuAn_CapNhat"] 2. Trong mục "Trong danh sách nhãn", chọn [Ẩn] (Hide) | D17: 2. Nhãn "DuAn_CapNhat" được ẩn khỏi danh sách chính và chuyển vào mục thu gọn [Danh sách mở rộng / More]. | E17: ManageLabels-7 | F17: Untested
A18: =IF(OR(B18<>"",D18<>""),"["&TEXT($B$2,"##")&"-"&TEXT(ROW()-8,"##")&"]","") | B18: Gán 1 nhãn cho email đơn lẻ | C18: Các bước thực hiện: 1. Tại Hộp thư đến, tích chọn 1 email 2. Nhấp biểu tượng [Nhãn] trên thanh công cụ phía trên 3. Tích chọn ["DuAn_CapNhat"] và nhấn [Áp dụng] (Apply) | D18: 3. Thẻ nhãn "DuAn_CapNhat" hiển thị ngay bên cạnh tiêu đề của email đó trong Hộp thư đến. | E18: ManageLabels-7 | F18: Untested
A19: =IF(OR(B19<>"",D19<>""),"["&TEXT($B$2,"##")&"-"&TEXT(ROW()-8,"##")&"]","") | B19: Gán nhiều nhãn cùng lúc cho 1 email | C19: Điều kiện tiên quyết: + Có sẵn 2 nhãn ["Nhan_A"] và ["Nhan_B"] Các bước thực hiện: 1. Tích chọn 1 email trong Hộp thư đến 2. Nhấp biểu tượng [Nhãn] -> Tích chọn cả ["Nhan_A"] và ["Nhan_B"] 3. Nhấn [Áp dụng] | D19: 3. Email hiển thị đồng thời cả 2 thẻ nhãn "Nhan_A" và "Nhan_B". | F19: Untested
A20: =IF(OR(B20<>"",D20<>""),"["&TEXT($B$2,"##")&"-"&TEXT(ROW()-8,"##")&"]","") | B20: Gán nhãn hàng loạt cho nhiều email cùng lúc | C20: Các bước thực hiện: 1. Tích chọn cùng lúc 3 email trong Hộp thư đến 2. Nhấp biểu tượng [Nhãn] -> Tích chọn ["DuAn_CapNhat"] -> Nhấn [Áp dụng] | D20: 2. Cả 3 email được chọn đều hiển thị thẻ nhãn "DuAn_CapNhat". | E20: ManageLabels-7 | F20: Untested
A21: =IF(OR(B21<>"",D21<>""),"["&TEXT($B$2,"##")&"-"&TEXT(ROW()-8,"##")&"]","") | B21: Gỡ bỏ nhãn đã gán khỏi email | C21: Điều kiện tiên quyết: + Có email đang được gán nhãn ["DuAn_CapNhat"] Các bước thực hiện: 1. Mở chi tiết email đó (hoặc quan sát ngoài danh sách) 2. Nhấp vào dấu [x] trên thẻ nhãn ["DuAn_CapNhat"] | D21: 2. Thẻ nhãn "DuAn_CapNhat" bị gỡ bỏ khỏi email đó. | E21: ManageLabels-7 | F21: Untested
A22: =IF(OR(B22<>"",D22<>""),"["&TEXT($B$2,"##")&"-"&TEXT(ROW()-8,"##")&"]","") | B22: Lọc danh sách thư theo Nhãn ở menu trái | C22: Điều kiện tiên quyết: + Có 2 email đã được gán nhãn ["DuAn_CapNhat"] Các bước thực hiện: 1. Nhấp chuột vào tên nhãn ["DuAn_CapNhat"] trên thanh menu bên trái | D22: 1. Màn hình danh sách thư chỉ lọc và hiển thị đúng 2 email mang nhãn "DuAn_CapNhat". | E22: ManageLabels-7 | F22: Untested
A23: =IF(OR(B23<>"",D23<>""),"["&TEXT($B$2,"##")&"-"&TEXT(ROW()-8,"##")&"]","") | B23: Xóa một nhãn đang tồn tại | C23: Các bước thực hiện: 1. Nhấp biểu tượng 3 chấm dọc cạnh nhãn ["DuAn_CapNhat"] 2. Chọn [Xóa nhãn] (Remove label) 3. Nhấp nút [Xóa] (Delete) trên hộp thoại xác nhận | D23: 3. Nhãn "DuAn_CapNhat" bị xóa khỏi menu trái và gỡ khỏi các thư; các email vẫn được giữ nguyên trong Hộp thư đến. | E23: ManageLabels-7 | F23: Untested
A24: =IF(OR(B24<>"",D24<>""),"["&TEXT($B$2,"##")&"-"&TEXT(ROW()-8,"##")&"]","") | B24: Hủy thao tác xóa nhãn | C24: Các bước thực hiện: 1. Nhấp biểu tượng 3 chấm dọc cạnh 1 nhãn -> Chọn [Xóa nhãn] 2. Nhấp nút [Hủy] (Cancel) trên hộp thoại xác nhận | D24: 2. Hộp thoại đóng lại và nhãn vẫn tồn tại bình thường trên thanh menu trái. | F24: Untested
A25: =IF(OR(B25<>"",D25<>""),"["&TEXT($B$2,"##")&"-"&TEXT(ROW()-8,"##")&"]","") | B25: Tạo nhãn mới trực tiếp từ thanh công cụ khi đang xem email | C25: Điều kiện tiên quyết: + Đang mở xem chi tiết một email Các bước thực hiện: 1. Nhấp biểu tượng [Nhãn] trên thanh công cụ 2. Nhập tên nhãn mới ["Nhan_Tu_Toolbar"] vào ô tìm kiếm nhãn 3. Nhấp tùy chọn [Tạo mới "Nhan_Tu_Toolbar"] 4. Nhấp nút [Tạo] trên popup xác nhận | D25: 4. Nhãn mới được tạo thành công, xuất hiện ở menu trái đồng thời được gán ngay vào email hiện tại. | F25: Untested
A26: =IF(OR(B26<>"",D26<>""),"["&TEXT($B$2,"##")&"-"&TEXT(ROW()-8,"##")&"]","") | B26: Tạo nhãn với tên chứa ký tự tiếng Việt có dấu và khoảng trắng | C26: Các bước thực hiện: 1. Nhấp dấu [+] tạo nhãn mới ở menu trái 2. Nhập tên nhãn ["Tài liệu Dự án 2026"] 3. Nhấp nút [Tạo] | D26: 3. Hệ thống tạo nhãn thành công; font chữ và dấu tiếng Việt hiển thị chính xác, không bị lỗi font hay ký tự lạ. | F26: Untested
A27: =IF(OR(B27<>"",D27<>""),"["&TEXT($B$2,"##")&"-"&TEXT(ROW()-8,"##")&"]","") | B27: Tạo nhãn chứa ký tự đặc biệt hợp lệ và emoji | C27: Các bước thực hiện: 1. Nhấp dấu [+] tạo nhãn mới 2. Nhập tên nhãn ["[KHẨN] - Dự án ⭐"] 3. Nhấp nút [Tạo] | D27: 3. Hệ thống cho phép tạo nhãn chứa các ký tự hợp lệ và hiển thị trực quan trên menu. | F27: Untested
A28: =IF(OR(B28<>"",D28<>""),"["&TEXT($B$2,"##")&"-"&TEXT(ROW()-8,"##")&"]","") | B28: Kiểm tra giới hạn độ dài tên nhãn (Boundary) | C28: Các bước thực hiện: 1. Nhấp dấu [+] tạo nhãn mới 2. Dán một chuỗi văn bản dài trên 225 ký tự vào ô tên nhãn 3. Nhấp nút [Tạo] | D28: 3. Hệ thống giới hạn tối đa độ dài ký tự cho phép hoặc cắt ngắn phù hợp, không làm vỡ layout giao diện menu trái. | F28: Untested
A29: =IF(OR(B29<>"",D29<>""),"["&TEXT($B$2,"##")&"-"&TEXT(ROW()-8,"##")&"]","") | B29: Tạo cấu trúc nhãn con lồng 3 cấp (Cha / Con / Cháu) | C29: Điều kiện tiên quyết: + Đã có sẵn nhãn cha ["DuAn_2026"] và nhãn con ["GiaiDoan_1"] Các bước thực hiện: 1. Nhấp dấu [+] tạo nhãn mới 2. Nhập tên ["Module_A"] 3. Tích [Đặt nhãn bên trong] và chọn ["DuAn_2026/GiaiDoan_1"] 4. Nhấp [Tạo] | D29: 4. Nhãn "Module_A" hiển thị thụt lề cấp 3 bên dưới "GiaiDoan_1" thuộc cấu trúc cây nhãn đa cấp. | E29: ManageLabels-3 | F29: Untested
A30: =IF(OR(B30<>"",D30<>""),"["&TEXT($B$2,"##")&"-"&TEXT(ROW()-8,"##")&"]","") | B30: Đổi màu nhãn bằng cách tùy chỉnh màu (Add custom color) | C30: Điều kiện tiên quyết: + Đang có nhãn ["DuAn_CapNhat"] Các bước thực hiện: 1. Nhấp dấu 3 chấm cạnh ["DuAn_CapNhat"] -> [Màu nhãn] 2. Chọn [Thêm màu tùy chỉnh] (Add custom color) 3. Chọn màu nền và màu chữ tùy ý rồi nhấp [Áp dụng] | D30: 3. Nhãn được áp dụng màu sắc tùy chỉnh theo đúng mã màu vừa thiết lập. | E30: ManageLabels-7 | F30: Untested
A31: =IF(OR(B31<>"",D31<>""),"["&TEXT($B$2,"##")&"-"&TEXT(ROW()-8,"##")&"]","") | B31: Xóa màu sắc tùy chỉnh của nhãn (Khôi phục màu mặc định) | C31: Các bước thực hiện: 1. Nhấp dấu 3 chấm cạnh nhãn đang có màu 2. Chọn [Màu nhãn] -> Nhấp [Xóa màu] (Remove color) | D31: 2. Thẻ nhãn quay về màu xám mặc định ban đầu của Gmail. | E31: ManageLabels-8 | F31: Untested
A32: =IF(OR(B32<>"",D32<>""),"["&TEXT($B$2,"##")&"-"&TEXT(ROW()-8,"##")&"]","") | B32: Gán nhãn bằng thao tác Kéo - Thả (Drag and Drop) | C32: Các bước thực hiện: 1. Tại Hộp thư đến, nhấp giữ chuột vào một hàng email 2. Kéo và thả email đó vào tên nhãn ["DuAn_CapNhat"] ở menu bên trái | D32: 2. Thẻ nhãn "DuAn_CapNhat" được gắn vào email; email vẫn hiển thị trong Hộp thư đến. | E32: ManageLabels-7 | F32: Untested
A33: =IF(OR(B33<>"",D33<>""),"["&TEXT($B$2,"##")&"-"&TEXT(ROW()-8,"##")&"]","") | B33: Chuyển email vào Nhãn bằng nút [Di chuyển tới] (Move to) | C33: Các bước thực hiện: 1. Tích chọn 1 email ở Hộp thư đến 2. Nhấp biểu tượng [Di chuyển tới] (Move to) trên thanh công cụ 3. Chọn nhãn ["DuAn_CapNhat"] | D33: 3. Email được gán nhãn "DuAn_CapNhat" và tự động lưu trữ, ẩn khỏi màn hình Hộp thư đến chính. | E33: ManageLabels-7 | F33: Untested
A34: =IF(OR(B34<>"",D34<>""),"["&TEXT($B$2,"##")&"-"&TEXT(ROW()-8,"##")&"]","") | B34: Tìm kiếm email theo cú pháp toán tử nhãn (label:) | C34: Điều kiện tiên quyết: + Có email đã gắn nhãn ["DuAn_CapNhat"] Các bước thực hiện: 1. Trên thanh tìm kiếm, gõ: ["label:DuAn_CapNhat"] 2. Nhấn [Enter] | D34: 2. Danh sách hiển thị chính xác các email đang mang nhãn "DuAn_CapNhat". | E34: ManageLabels-7 | F34: Untested
A35: =IF(OR(B35<>"",D35<>""),"["&TEXT($B$2,"##")&"-"&TEXT(ROW()-8,"##")&"]","") | B35: Xóa nhãn cha đang chứa nhãn con bên trong | C35: Điều kiện tiên quyết: + Nhãn ["DuAn_2026"] chứa nhãn con ["GiaiDoan_1"] Các bước thực hiện: 1. Nhấp dấu 3 chấm cạnh nhãn cha ["DuAn_2026"] -> [Xóa nhãn] 2. Nhấp [Xóa] trên popup cảnh báo | D35: 2. Nhãn cha bị xóa; các nhãn con được đưa ra cấp gốc, và toàn bộ email không bị mất. | E35: ManageLabels-3 | F35: Untested

Sheet Test Report
B1: TEST REPORT
B3: Project Name | C3: =Cover!C4 | E3: Creator | G3: Trương Trọng Nhân - 23130217
B4: Project Code | C4: =Cover!C5 | E4: Reviewer/Approver
B5: Document Code | C5: =C4&"_"&"Test Report"&"_"&"v1.0" | E5: Issue Date
B6: Notes | C6: Báo cáo kiểm thử 3 chức năng của Thành viên 3: Search Mail (30 TC), Reply - Reply All - Forward (23 TC), Manage Labels (27 TC). Tổng cộng: 80 Test Cases.
B10: No | C10: Module code | D10: Pass | E10: Fail | F10: Untested | G10: Blocked | H10: Skipped | I10: Number of test cases
B11: 1 | C11: ='Search Mail'!B2 | D11: ='Search Mail'!A6 | E11: ='Search Mail'!B6 | F11: ='Search Mail'!C6 | G11: ='Search Mail'!D6 | H11: ='Search Mail'!E6 | I11: ='Search Mail'!F6
B12: 2 | C12: =Reply!B2 | D12: =Reply!A6 | E12: =Reply!B6 | F12: =Reply!C6 | G12: =Reply!D6 | H12: =Reply!E6 | I12: =Reply!F6
B13: 3 | C13: ='Reply All'!B2 | D13: ='Reply All'!A6 | E13: ='Reply All'!B6 | F13: ='Reply All'!C6 | G13: ='Reply All'!D6 | H13: ='Reply All'!E6 | I13: ='Reply All'!F6
B14: 4 | C14: =Forward!B2 | D14: =Forward!A6 | E14: =Forward!B6 | F14: =Forward!C6 | G14: =Forward!D6 | H14: =Forward!E6 | I14: =Forward!F6
B15: 5 | C15: ='Manage Labels'!B2 | D15: ='Manage Labels'!A6 | E15: ='Manage Labels'!B6 | F15: ='Manage Labels'!C6 | G15: ='Manage Labels'!D6 | H15: ='Manage Labels'!E6 | I15: ='Manage Labels'!F6
C17: Sub total | D17: =SUM(D11:D15) | E17: =SUM(E11:E15) | F17: =SUM(F11:F15) | G17: =SUM(G11:G15) | H17: =SUM(H11:H15) | I17: =SUM(I11:I15)
C19: Test coverage | E19: =(D17+E17)*100/(I17-H17-G17) | F19: %
C20: Test successful coverage | E20: =IFERROR(D17*100/(D17+E17),0) | F20: %
